2024-06-10 15:56:19,888 *** Start ***
2024-06-10 15:56:20,356 
Traceback (most recent call last):
  File "g:\OneDrive\Desktop\AHS Work\SASMigration\NAACCR_XML_Parse\app.py", line 27, in Process
    is_valid, error_log = self.validate_xml(xml_path, xsd_path)
                          ^^^^^^^^^^^^^^^^^^^^^^^^^^^^^^^^^^^^^
  File "g:\OneDrive\Desktop\AHS Work\SASMigration\NAACCR_XML_Parse\app.py", line 79, in validate_xml
    with open(xsd_path, 'r') as xsd_file:
         ^^^^^^^^^^^^^^^^^^^
FileNotFoundError: [Errno 2] No such file or directory: 'SASMigration\\NAACCR_XML_Parse\\naaccr_data_1.6.xsd'
2024-06-10 15:56:56,279 *** Start ***
2024-06-10 15:56:56,291 
Traceback (most recent call last):
  File "g:\OneDrive\Desktop\AHS Work\SASMigration\NAACCR_XML_Parse\app.py", line 27, in Process
    is_valid, error_log = self.validate_xml(xml_path, xsd_path)
                          ^^^^^^^^^^^^^^^^^^^^^^^^^^^^^^^^^^^^^
  File "g:\OneDrive\Desktop\AHS Work\SASMigration\NAACCR_XML_Parse\app.py", line 79, in validate_xml
    with open(xsd_path, 'r') as xsd_file:
         ^^^^^^^^^^^^^^^^^^^
FileNotFoundError: [Errno 2] No such file or directory: 'SASMigration/NAACCR_XML_Parse/naaccr_data_1.6.xsd'
2024-06-10 16:07:34,171 *** Start ***
2024-06-10 16:07:34,182 
Traceback (most recent call last):
  File "g:\OneDrive\Desktop\AHS Work\SASMigration\NAACCR_XML_Parse\app.py", line 27, in Process
    is_valid, error_log = self.validate_xml(xml_path, xsd_path)
                          ^^^^^^^^^^^^^^^^^^^^^^^^^^^^^^^^^^^^^
  File "g:\OneDrive\Desktop\AHS Work\SASMigration\NAACCR_XML_Parse\app.py", line 79, in validate_xml
    with open(xsd_path, 'r') as xsd_file:
         ^^^^^^^^^^^^^^^^^^^
FileNotFoundError: [Errno 2] No such file or directory: 'SASMigration/NAACCR_XML_Parse/naaccr_data_1.6.xsd'
2024-06-10 16:07:43,574 *** Start ***
2024-06-10 16:07:43,585 
Traceback (most recent call last):
  File "g:\OneDrive\Desktop\AHS Work\SASMigration\NAACCR_XML_Parse\app.py", line 27, in Process
    is_valid, error_log = self.validate_xml(xml_path, xsd_path)
                          ^^^^^^^^^^^^^^^^^^^^^^^^^^^^^^^^^^^^^
  File "g:\OneDrive\Desktop\AHS Work\SASMigration\NAACCR_XML_Parse\app.py", line 79, in validate_xml
    with open(xsd_path, 'r') as xsd_file:
         ^^^^^^^^^^^^^^^^^^^
FileNotFoundError: [Errno 2] No such file or directory: 'SASMigration/NAACCR_XML_Parse/naaccr_data_1.6.xsd'
2024-06-10 16:09:17,038 *** Start ***
2024-06-10 16:09:17,050 
Traceback (most recent call last):
  File "g:\OneDrive\Desktop\AHS Work\SASMigration\NAACCR_XML_Parse\app.py", line 27, in Process
    is_valid, error_log = self.validate_xml(xml_path, xsd_path)
                          ^^^^^^^^^^^^^^^^^^^^^^^^^^^^^^^^^^^^^
  File "g:\OneDrive\Desktop\AHS Work\SASMigration\NAACCR_XML_Parse\app.py", line 79, in validate_xml
    with open(xsd_path, 'r') as xsd_file:
         ^^^^^^^^^^^^^^^^^^^
FileNotFoundError: [Errno 2] No such file or directory: 'G:\\OneDrive\\Desktop\\AHS Work\\SASMigration\\SASMigration\\NAACCR_XML_Parse\\naaccr_data_1.6.xsd'
2024-06-10 16:09:31,036 *** Start ***
2024-06-10 16:09:31,047 XML path: G:\OneDrive\Desktop\AHS Work\SASMigration\SASMigration\NAACCR_XML_Parse\naaccr-dictionary-230.xml
2024-06-10 16:09:31,047 XSD path: G:\OneDrive\Desktop\AHS Work\SASMigration\SASMigration\NAACCR_XML_Parse\naaccr_data_1.6.xsd
2024-06-10 16:09:31,047 XSD file not found: G:\OneDrive\Desktop\AHS Work\SASMigration\SASMigration\NAACCR_XML_Parse\naaccr_data_1.6.xsd
2024-06-10 16:14:36,891 *** Start ***
2024-06-10 16:14:36,906 XML path: G:\OneDrive\Desktop\AHS Work\SASMigration\NAACCR_XML_Parse\naaccr-dictionary-230.xml
2024-06-10 16:14:36,906 XSD path: G:\OneDrive\Desktop\AHS Work\SASMigration\NAACCR_XML_Parse\naaccr_data_1.6.xsd
2024-06-10 16:14:36,907 Files in directory 'G:\OneDrive\Desktop\AHS Work\SASMigration\NAACCR_XML_Parse': ['app.py', 'data', 'handler', 'model', 'naaccr-dictionary-230.xml', 'naaccr_data_1.6.xsd', 'README.md', 'repository.py', 'utility.py', '__pycache__']
2024-06-10 16:14:36,911 The XML file is invalid.
2024-06-10 16:14:36,911 Element '{http://naaccr.org/naaccrxml}NaaccrDictionary': No matching global declaration available for the validation root.
2024-06-10 16:15:36,571 Exception occurred
Traceback (most recent call last):
  File "g:\OneDrive\Desktop\AHS Work\SASMigration\NAACCR_XML_Parse\app.py", line 48, in Process
    connection = self.connect_to_oracle(username, password, dsn)
                 ^^^^^^^^^^^^^^^^^^^^^^^^^^^^^^^^^^^^^^^^^^^^^^^
  File "g:\OneDrive\Desktop\AHS Work\SASMigration\NAACCR_XML_Parse\app.py", line 99, in connect_to_oracle
    connection = cx_Oracle.connect(username, password, dsn)
                 ^^^^^^^^^^^^^^^^^^^^^^^^^^^^^^^^^^^^^^^^^^
cx_Oracle.DatabaseError: ORA-12154: TNS:could not resolve the connect identifier specified
2024-06-10 16:16:54,548 *** Start ***
2024-06-10 16:16:54,560 XML path: G:\OneDrive\Desktop\AHS Work\SASMigration\NAACCR_XML_Parse\naaccr-dictionary-230.xml
2024-06-10 16:16:54,560 XSD path: G:\OneDrive\Desktop\AHS Work\SASMigration\NAACCR_XML_Parse\naaccr_data_1.6.xsd
2024-06-10 16:16:54,561 Files in directory 'G:\OneDrive\Desktop\AHS Work\SASMigration\NAACCR_XML_Parse': ['app.py', 'data', 'handler', 'model', 'naaccr-dictionary-230.xml', 'naaccr_data_1.6.xsd', 'README.md', 'repository.py', 'utility.py', '__pycache__']
2024-06-10 16:16:54,565 The XML file is invalid.
2024-06-10 16:16:54,565 Element '{http://naaccr.org/naaccrxml}NaaccrDictionary': No matching global declaration available for the validation root.
2024-06-10 16:17:53,859 Exception occurred
Traceback (most recent call last):
  File "g:\OneDrive\Desktop\AHS Work\SASMigration\NAACCR_XML_Parse\app.py", line 48, in Process
    connection = self.connect_to_oracle(username, password, dsn)
                 ^^^^^^^^^^^^^^^^^^^^^^^^^^^^^^^^^^^^^^^^^^^^^^^
  File "g:\OneDrive\Desktop\AHS Work\SASMigration\NAACCR_XML_Parse\app.py", line 99, in connect_to_oracle
    connection = cx_Oracle.connect(username, password, dsn)
                 ^^^^^^^^^^^^^^^^^^^^^^^^^^^^^^^^^^^^^^^^^^
cx_Oracle.DatabaseError: ORA-12154: TNS:could not resolve the connect identifier specified
